module.exports = catchAsync = fn => {              // we repace our try catch for async functions in this single error handling function
    return (req,res,next) => {
      fn(req,res,next).catch(function(err){
        next(err)
      })
    }
  }